Workbook

Sheet Raw Data
A1: Manufacturer | B1: Model | C1: Sales_in_thousands | D1: __year_resale_value | E1: Vehicle_type | F1: Price_in_thousands | G1: Engine_size | H1: Horsepower | I1: Wheelbase | J1: Width | K1: Length | L1: Curb_weight | M1: Fuel_capacity | N1: Fuel_efficiency | O1: Latest_Launch | P1: Power_perf_factor
A2: Acura | B2: Integra | C2: 16.919 | D2: 16.36 | E2: Passenger | F2: 21.5 | G2: 1.8 | H2: 140 | I2: 101.2 | J2: 67.3 | K2: 172.4 | L2: 2.639 | M2: 13.2 | N2: 28 | O2: 2/2/2012 | P2: 58.28015
A3: Acura | B3: TL | C3: 39.384 | D3: 19.875 | E3: Passenger | F3: 28.4 | G3: 3.2 | H3: 225 | I3: 108.1 | J3: 70.3 | K3: 192.9 | L3: 3.517 | M3: 17.2 | N3: 25 | O3: 6/3/2011 | P3: 91.370778
A4: Acura | B4: CL | C4: 14.114 | D4: 18.225 | E4: Passenger | G4: 3.2 | H4: 225 | I4: 106.9 | J4: 70.6 | K4: 192 | L4: 3.47 | M4: 17.2 | N4: 26 | O4: 1/4/2012
A5: Acura | B5: RL | C5: 8.588 | D5: 29.725 | E5: Passenger | F5: 42 | G5: 3.5 | H5: 210 | I5: 114.6 | J5: 71.4 | K5: 196.6 | L5: 3.85 | M5: 18 | N5: 22 | O5: 3/10/2011 | P5: 91.389779
A6: Audi | B6: A4 | C6: 20.397 | D6: 22.255 | E6: Passenger | F6: 23.99 | G6: 1.8 | H6: 150 | I6: 102.6 | J6: 68.2 | K6: 178 | L6: 2.998 | M6: 16.4 | N6: 27 | O6: 10/8/2011 | P6: 62.777639
A7: Audi | B7: A6 | C7: 18.78 | D7: 23.555 | E7: Passenger | F7: 33.95 | G7: 2.8 | H7: 200 | I7: 108.7 | J7: 76.1 | K7: 192 | L7: 3.561 | M7: 18.5 | N7: 22 | O7: 8/9/2011 | P7: 84.565105
A8: Audi | B8: A8 | C8: 1.38 | D8: 39 | E8: Passenger | F8: 62 | G8: 4.2 | H8: 310 | I8: 113 | J8: 74 | K8: 198.2 | L8: 3.902 | M8: 23.7 | N8: 21 | O8: 2/27/2012 | P8: 134.65686
A9: BMW | B9: 323i | C9: 19.747 | E9: Passenger | F9: 26.99 | G9: 2.5 | H9: 170 | I9: 107.3 | J9: 68.4 | K9: 176 | L9: 3.179 | M9: 16.6 | N9: 26 | O9: 6/28/2011 | P9: 71.191207
A10: BMW | B10: 328i | C10: 9.231 | D10: 28.675 | E10: Passenger | F10: 33.4 | G10: 2.8 | H10: 193 | I10: 107.3 | J10: 68.5 | K10: 176 | L10: 3.197 | M10: 16.6 | N10: 24 | O10: 1/29/2012 | P10: 81.877069
A11: BMW | B11: 528i | C11: 17.527 | D11: 36.125 | E11: Passenger | F11: 38.9 | G11: 2.8 | H11: 193 | I11: 111.4 | J11: 70.9 | K11: 188 | L11: 3.472 | M11: 18.5 | N11: 25 | O11: 4/4/2011 | P11: 83.998724
A12: Buick | B12: Century | C12: 91.561 | D12: 12.475 | E12: Passenger | F12: 21.975 | G12: 3.1 | H12: 175 | I12: 109 | J12: 72.7 | K12: 194.6 | L12: 3.368 | M12: 17.5 | N12: 25 | O12: 11/2/2011 | P12: 71.181451
A13: Buick | B13: Regal | C13: 39.35 | D13: 13.74 | E13: Passenger | F13: 25.3 | G13: 3.8 | H13: 240 | I13: 109 | J13: 72.7 | K13: 196.2 | L13: 3.543 | M13: 17.5 | N13: 23 | O13: 9/3/2011 | P13: 95.636703
A14: Buick | B14: Park Avenue | C14: 27.851 | D14: 20.19 | E14: Passenger | F14: 31.965 | G14: 3.8 | H14: 205 | I14: 113.8 | J14: 74.7 | K14: 206.8 | L14: 3.778 | M14: 18.5 | N14: 24 | O14: 3/23/2012 | P14: 85.828408
A15: Buick | B15: LeSabre | C15: 83.257 | D15: 13.36 | E15: Passenger | F15: 27.885 | G15: 3.8 | H15: 205 | I15: 112.2 | J15: 73.5 | K15: 200 | L15: 3.591 | M15: 17.5 | N15: 25 | O15: 7/23/2011 | P15: 84.254526
A16: Cadillac | B16: DeVille | C16: 63.729 | D16: 22.525 | E16: Passenger | F16: 39.895 | G16: 4.6 | H16: 275 | I16: 115.3 | J16: 74.5 | K16: 207.2 | L16: 3.978 | M16: 18.5 | N16: 22 | O16: 2/23/2012 | P16: 113.8546
A17: Cadillac | B17: Seville | C17: 15.943 | D17: 27.1 | E17: Passenger | F17: 44.475 | G17: 4.6 | H17: 275 | I17: 112.2 | J17: 75 | K17: 201 | M17: 18.5 | N17: 22 | O17: 4/29/2011 | P17: 115.62136
A18: Cadillac | B18: Eldorado | C18: 6.536 | D18: 25.725 | E18: Passenger | F18: 39.665 | G18: 4.6 | H18: 275 | I18: 108 | J18: 75.5 | K18: 200.6 | L18: 3.843 | M18: 19 | N18: 22 | O18: 11/27/2011 | P18: 113.76587
A19: Cadillac | B19: Catera | C19: 11.185 | D19: 18.225 | E19: Passenger | F19: 31.01 | G19: 3 | H19: 200 | I19: 107.4 | J19: 70.3 | K19: 194.8 | L19: 3.77 | M19: 18 | N19: 22 | O19: 9/28/2011 | P19: 83.483094
A20: Cadillac | B20: Escalade | C20: 14.785 | E20: Car | F20: 46.225 | G20: 5.7 | H20: 255 | I20: 117.5 | J20: 77 | K20: 201.2 | L20: 5.572 | M20: 30 | N20: 15 | O20: 4/17/2012 | P20: 109.50912
A21: Chevrolet | B21: Cavalier | C21: 145.519 | D21: 9.25 | E21: Passenger | F21: 13.26 | G21: 2.2 | H21: 115 | I21: 104.1 | J21: 67.9 | K21: 180.9 | L21: 2.676 | M21: 14.3 | N21: 27 | O21: 8/17/2011 | P21: 46.363347
A22: Chevrolet | B22: Malibu | C22: 135.126 | D22: 11.225 | E22: Passenger | F22: 16.535 | G22: 3.1 | H22: 170 | I22: 107 | J22: 69.4 | K22: 190.4 | L22: 3.051 | M22: 15 | N22: 25 | O22: 3/19/2012 | P22: 67.314462
A23: Chevrolet | B23: Lumina | C23: 24.629 | D23: 10.31 | E23: Passenger | F23: 18.89 | G23: 3.1 | H23: 175 | I23: 107.5 | J23: 72.5 | K23: 200.9 | L23: 3.33 | M23: 16.6 | N23: 25 | O23: 5/24/2011 | P23: 69.991396
A24: Chevrolet | B24: Monte Carlo | C24: 42.593 | D24: 11.525 | E24: Passenger | F24: 19.39 | G24: 3.4 | H24: 180 | I24: 110.5 | J24: 72.7 | K24: 197.9 | L24: 3.34 | M24: 17 | N24: 27 | O24: 12/22/2011 | P24: 72.030917
A25: Chevrolet | B25: Camaro | C25: 26.402 | D25: 13.025 | E25: Passenger | F25: 24.34 | G25: 3.8 | H25: 200 | I25: 101.1 | J25: 74.1 | K25: 193.2 | L25: 3.5 | M25: 16.8 | N25: 25 | O25: 10/23/2011 | P25: 81.118543
A26: Chevrolet | B26: Corvette | C26: 17.947 | D26: 36.225 | E26: Passenger | F26: 45.705 | G26: 5.7 | H26: 345 | I26: 104.5 | J26: 73.6 | K26: 179.7 | L26: 3.21 | M26: 19.1 | N26: 22 | O26: 5/12/2012 | P26: 141.14115
A27: Chevrolet | B27: Prizm | C27: 32.299 | D27: 9.125 | E27: Passenger | F27: 13.96 | G27: 1.8 | H27: 120 | I27: 97.1 | J27: 66.7 | K27: 174.3 | L27: 2.398 | M27: 13.2 | N27: 33 | O27: 9/11/2011 | P27: 48.297636
A28: Chevrolet | B28: Metro | C28: 21.855 | D28: 5.16 | E28: Passenger | F28: 9.235 | G28: 1 | H28: 55 | I28: 93.1 | J28: 62.6 | K28: 149.4 | L28: 1.895 | M28: 10.3 | N28: 45 | O28: 4/13/2012 | P28: 23.276272
A29: Chevrolet | B29: Impala | C29: 107.995 | E29: Passenger | F29: 18.89 | G29: 3.4 | H29: 180 | I29: 110.5 | J29: 73 | K29: 200 | L29: 3.389 | M29: 17 | N29: 27 | O29: 6/18/2011 | P29: 71.838039
A30: Chrysler | B30: Sebring Coupe | C30: 7.854 | D30: 12.36 | E30: Passenger | F30: 19.84 | G30: 2.5 | H30: 163 | I30: 103.7 | J30: 69.7 | K30: 190.9 | L30: 2.967 | M30: 15.9 | N30: 24 | O30: 1/16/2012 | P30: 65.957184
A31: Chrysler | B31: Sebring Conv. | C31: 32.775 | D31: 14.18 | E31: Passenger | F31: 24.495 | G31: 2.5 | H31: 168 | I31: 106 | J31: 69.2 | K31: 193 | L31: 3.332 | M31: 16 | N31: 24 | O31: 11/17/2011 | P31: 69.521355
A32: Chrysler | B32: Concorde | C32: 31.148 | D32: 13.725 | E32: Passenger | F32: 22.245 | G32: 2.7 | H32: 200 | I32: 113 | J32: 74.4 | K32: 209.1 | L32: 3.452 | M32: 17 | N32: 26 | O32: 6/6/2012 | P32: 80.023782
A33: Chrysler | B33: Cirrus | C33: 32.306 | D33: 12.64 | E33: Passenger | F33: 16.48 | G33: 2 | H33: 132 | I33: 108 | J33: 71 | K33: 186 | L33: 2.911 | M33: 16 | N33: 27 | O33: 10/6/2011 | P33: 53.5662
A34: Chrysler | B34: LHS | C34: 13.462 | D34: 17.325 | E34: Passenger | F34: 28.34 | G34: 3.5 | H34: 253 | I34: 113 | J34: 74.4 | K34: 207.7 | L34: 3.564 | M34: 17 | N34: 23 | O34: 5/8/2012 | P34: 101.32928
A35: Chrysler | B35: Town & Country | C35: 53.48 | D35: 19.54 | E35: Car | O35: 7/13/2011
A36: Chrysler | B36: 300M | C36: 30.696 | E36: Passenger | F36: 29.185 | G36: 3.5 | H36: 253 | I36: 113 | J36: 74.4 | K36: 197.8 | L36: 3.567 | M36: 17 | N36: 23 | O36: 2/10/2012 | P36: 101.65524
A37: Dodge | B37: Neon | C37: 76.034 | D37: 7.75 | E37: Passenger | F37: 12.64 | G37: 2 | H37: 132 | I37: 105 | J37: 74.4 | K37: 174.4 | L37: 2.567 | M37: 12.5 | N37: 29 | O37: 12/12/2011 | P37: 52.084899
A38: Dodge | B38: Avenger | C38: 4.734 | D38: 12.545 | E38: Passenger | F38: 19.045 | G38: 2.5 | H38: 163 | I38: 103.7 | J38: 69.1 | K38: 190.2 | L38: 2.879 | M38: 15.9 | N38: 24 | O38: 7/1/2012 | P38: 65.650508
A39: Dodge | B39: Stratus | C39: 71.186 | D39: 10.185 | E39: Passenger | F39: 20.23 | G39: 2.5 | H39: 168 | I39: 108 | J39: 71 | K39: 186 | L39: 3.058 | M39: 16 | N39: 24 | O39: 10/31/2011 | P39: 67.876108
A40: Dodge | B40: Intrepid | C40: 88.028 | D40: 12.275 | E40: Passenger | F40: 22.505 | G40: 2.7 | H40: 202 | I40: 113 | J40: 74.7 | K40: 203.7 | L40: 3.489 | M40: 17 | O40: 6/2/2012 | P40: 80.83147
...

Sheet Cleaned Data
A1: Manufacturer | B1: Model | C1: Vehicle_Segment | D1: Sales_Units_Thousands | E1: Price_Thousands_USD | F1: Engine_Size_L | G1: Horsepower | H1: Wheelbase_in | I1: Width_in | J1: Length_in | K1: Curb_Weight_Tons | L1: Fuel_Capacity_Gal | M1: Fuel_Efficiency_MPG | N1: Resale_Value_Thousands | O1: Launch_Date | P1: Launch_Year | Q1: Launch_Month | R1: Power_Perf_Factor | S1: Revenue_Millions_USD | T1: Price_Tier | U1: Data_Complete | V1: Sales_Rank | W1: Revenue_Rank
A2: Acura | B2: Integra | C2: Passenger Car | D2: 16.919 | E2: 21.5 | F2: 1.8 | G2: 140 | H2: 101.2 | I2: 67.3 | J2: 172.4 | K2: 2.639 | L2: 13.2 | M2: 28 | N2: 16.36 | O2: 40941 | P2: =YEAR(O2) -> 2012 | Q2: =TEXT(O2,"mmm") -> Feb | R2: 58.28015 | S2: =IFERROR(D2*E2,"") -> 363.7585 | T2: =IF(E2="","Unknown",_xlfn.IFS(E2<15,"Budget",E2<30,"Mid-range",TRUE(),"Luxury")) -> Mid-range | U2: =IF(COUNTBLANK(D2:R2)>0,"Incomplete","Complete") -> Complete | V2: =IFERROR(RANK(D2,$D$2:$D$158),"") -> 109 | W2: =IFERROR(RANK(S2,$S$2:$S$158),"") -> 119
A3: Acura | B3: TL | C3: Passenger Car | D3: 39.384 | E3: 28.4 | F3: 3.2 | G3: 225 | H3: 108.1 | I3: 70.3 | J3: 192.9 | K3: 3.517 | L3: 17.2 | M3: 25 | N3: 19.875 | O3: 40697 | P3: =YEAR(O3) -> 2011 | Q3: =TEXT(O3,"mmm") -> Jun | R3: 91.370778 | S3: =IFERROR(D3*E3,"") -> 1118.5056 | T3: =IF(E3="","Unknown",_xlfn.IFS(E3<15,"Budget",E3<30,"Mid-range",TRUE(),"Luxury")) -> Mid-range | U3: =IF(COUNTBLANK(D3:R3)>0,"Incomplete","Complete") -> Complete | V3: =IFERROR(RANK(D3,$D$2:$D$158),"") -> 64 | W3: =IFERROR(RANK(S3,$S$2:$S$158),"") -> 48
A4: Acura | B4: CL | C4: Passenger Car | D4: 14.114 | F4: 3.2 | G4: 225 | H4: 106.9 | I4: 70.6 | J4: 192 | K4: 3.47 | L4: 17.2 | M4: 26 | N4: 18.225 | O4: 40912 | P4: =YEAR(O4) -> 2012 | Q4: =TEXT(O4,"mmm") -> Jan | S4: =IFERROR(D4*E4,"") -> 0 | T4: =IF(E4="","Unknown",_xlfn.IFS(E4<15,"Budget",E4<30,"Mid-range",TRUE(),"Luxury")) -> Unknown | U4: =IF(COUNTBLANK(D4:R4)>0,"Incomplete","Complete") -> Incomplete | V4: =IFERROR(RANK(D4,$D$2:$D$158),"") -> 118 | W4: =IFERROR(RANK(S4,$S$2:$S$158),"") -> 156
A5: Acura | B5: RL | C5: Passenger Car | D5: 8.588 | E5: 42 | F5: 3.5 | G5: 210 | H5: 114.6 | I5: 71.4 | J5: 196.6 | K5: 3.85 | L5: 18 | M5: 22 | N5: 29.725 | O5: 40612 | P5: =YEAR(O5) -> 2011 | Q5: =TEXT(O5,"mmm") -> Mar | R5: 91.389779 | S5: =IFERROR(D5*E5,"") -> 360.696 | T5: =IF(E5="","Unknown",_xlfn.IFS(E5<15,"Budget",E5<30,"Mid-range",TRUE(),"Luxury")) -> Luxury | U5: =IF(COUNTBLANK(D5:R5)>0,"Incomplete","Complete") -> Complete | V5: =IFERROR(RANK(D5,$D$2:$D$158),"") -> 134 | W5: =IFERROR(RANK(S5,$S$2:$S$158),"") -> 120
A6: Audi | B6: A4 | C6: Passenger Car | D6: 20.397 | E6: 23.99 | F6: 1.8 | G6: 150 | H6: 102.6 | I6: 68.2 | J6: 178 | K6: 2.998 | L6: 16.4 | M6: 27 | N6: 22.255 | O6: 40824 | P6: =YEAR(O6) -> 2011 | Q6: =TEXT(O6,"mmm") -> Oct | R6: 62.777639 | S6: =IFERROR(D6*E6,"") -> 489.32403 | T6: =IF(E6="","Unknown",_xlfn.IFS(E6<15,"Budget",E6<30,"Mid-range",TRUE(),"Luxury")) -> Mid-range | U6: =IF(COUNTBLANK(D6:R6)>0,"Incomplete","Complete") -> Complete | V6: =IFERROR(RANK(D6,$D$2:$D$158),"") -> 97 | W6: =IFERROR(RANK(S6,$S$2:$S$158),"") -> 102
A7: Audi | B7: A6 | C7: Passenger Car | D7: 18.78 | E7: 33.95 | F7: 2.8 | G7: 200 | H7: 108.7 | I7: 76.1 | J7: 192 | K7: 3.561 | L7: 18.5 | M7: 22 | N7: 23.555 | O7: 40764 | P7: =YEAR(O7) -> 2011 | Q7: =TEXT(O7,"mmm") -> Aug | R7: 84.565105 | S7: =IFERROR(D7*E7,"") -> 637.581 | T7: =IF(E7="","Unknown",_xlfn.IFS(E7<15,"Budget",E7<30,"Mid-range",TRUE(),"Luxury")) -> Luxury | U7: =IF(COUNTBLANK(D7:R7)>0,"Incomplete","Complete") -> Complete | V7: =IFERROR(RANK(D7,$D$2:$D$158),"") -> 103 | W7: =IFERROR(RANK(S7,$S$2:$S$158),"") -> 86
A8: Audi | B8: A8 | C8: Passenger Car | D8: 1.38 | E8: 62 | F8: 4.2 | G8: 310 | H8: 113 | I8: 74 | J8: 198.2 | K8: 3.902 | L8: 23.7 | M8: 21 | N8: 39 | O8: 40966 | P8: =YEAR(O8) -> 2012 | Q8: =TEXT(O8,"mmm") -> Feb | R8: 134.65686 | S8: =IFERROR(D8*E8,"") -> 85.56 | T8: =IF(E8="","Unknown",_xlfn.IFS(E8<15,"Budget",E8<30,"Mid-range",TRUE(),"Luxury")) -> Luxury | U8: =IF(COUNTBLANK(D8:R8)>0,"Incomplete","Complete") -> Complete | V8: =IFERROR(RANK(D8,$D$2:$D$158),"") -> 152 | W8: =IFERROR(RANK(S8,$S$2:$S$158),"") -> 147
A9: BMW | B9: 323i | C9: Passenger Car | D9: 19.747 | E9: 26.99 | F9: 2.5 | G9: 170 | H9: 107.3 | I9: 68.4 | J9: 176 | K9: 3.179 | L9: 16.6 | M9: 26 | O9: 40722 | P9: =YEAR(O9) -> 2011 | Q9: =TEXT(O9,"mmm") -> Jun | R9: 71.191207 | S9: =IFERROR(D9*E9,"") -> 532.97153 | T9: =IF(E9="","Unknown",_xlfn.IFS(E9<15,"Budget",E9<30,"Mid-range",TRUE(),"Luxury")) -> Mid-range | U9: =IF(COUNTBLANK(D9:R9)>0,"Incomplete","Complete") -> Incomplete | V9: =IFERROR(RANK(D9,$D$2:$D$158),"") -> 101 | W9: =IFERROR(RANK(S9,$S$2:$S$158),"") -> 96
A10: BMW | B10: 328i | C10: Passenger Car | D10: 9.231 | E10: 33.4 | F10: 2.8 | G10: 193 | H10: 107.3 | I10: 68.5 | J10: 176 | K10: 3.197 | L10: 16.6 | M10: 24 | N10: 28.675 | O10: 40937 | P10: =YEAR(O10) -> 2012 | Q10: =TEXT(O10,"mmm") -> Jan | R10: 81.877069 | S10: =IFERROR(D10*E10,"") -> 308.3154 | T10: =IF(E10="","Unknown",_xlfn.IFS(E10<15,"Budget",E10<30,"Mid-range",TRUE(),"Luxury")) -> Luxury | U10: =IF(COUNTBLANK(D10:R10)>0,"Incomplete","Complete") -> Complete | V10: =IFERROR(RANK(D10,$D$2:$D$158),"") -> 130 | W10: =IFERROR(RANK(S10,$S$2:$S$158),"") -> 128
A11: BMW | B11: 528i | C11: Passenger Car | D11: 17.527 | E11: 38.9 | F11: 2.8 | G11: 193 | H11: 111.4 | I11: 70.9 | J11: 188 | K11: 3.472 | L11: 18.5 | M11: 25 | N11: 36.125 | O11: 40637 | P11: =YEAR(O11) -> 2011 | Q11: =TEXT(O11,"mmm") -> Apr | R11: 83.998724 | S11: =IFERROR(D11*E11,"") -> 681.8003 | T11: =IF(E11="","Unknown",_xlfn.IFS(E11<15,"Budget",E11<30,"Mid-range",TRUE(),"Luxury")) -> Luxury | U11: =IF(COUNTBLANK(D11:R11)>0,"Incomplete","Complete") -> Complete | V11: =IFERROR(RANK(D11,$D$2:$D$158),"") -> 107 | W11: =IFERROR(RANK(S11,$S$2:$S$158),"") -> 82
A12: Buick | B12: Century | C12: Passenger Car | D12: 91.561 | E12: 21.975 | F12: 3.1 | G12: 175 | H12: 109 | I12: 72.7 | J12: 194.6 | K12: 3.368 | L12: 17.5 | M12: 25 | N12: 12.475 | O12: 40849 | P12: =YEAR(O12) -> 2011 | Q12: =TEXT(O12,"mmm") -> Nov | R12: 71.181451 | S12: =IFERROR(D12*E12,"") -> 2012.053 | T12: =IF(E12="","Unknown",_xlfn.IFS(E12<15,"Budget",E12<30,"Mid-range",TRUE(),"Luxury")) -> Mid-range | U12: =IF(COUNTBLANK(D12:R12)>0,"Incomplete","Complete") -> Complete | V12: =IFERROR(RANK(D12,$D$2:$D$158),"") -> 23 | W12: =IFERROR(RANK(S12,$S$2:$S$158),"") -> 23
A13: Buick | B13: Regal | C13: Passenger Car | D13: 39.35 | E13: 25.3 | F13: 3.8 | G13: 240 | H13: 109 | I13: 72.7 | J13: 196.2 | K13: 3.543 | L13: 17.5 | M13: 23 | N13: 13.74 | O13: 40789 | P13: =YEAR(O13) -> 2011 | Q13: =TEXT(O13,"mmm") -> Sep | R13: 95.636703 | S13: =IFERROR(D13*E13,"") -> 995.555 | T13: =IF(E13="","Unknown",_xlfn.IFS(E13<15,"Budget",E13<30,"Mid-range",TRUE(),"Luxury")) -> Mid-range | U13: =IF(COUNTBLANK(D13:R13)>0,"Incomplete","Complete") -> Complete | V13: =IFERROR(RANK(D13,$D$2:$D$158),"") -> 65 | W13: =IFERROR(RANK(S13,$S$2:$S$158),"") -> 54
A14: Buick | B14: Park Avenue | C14: Passenger Car | D14: 27.851 | E14: 31.965 | F14: 3.8 | G14: 205 | H14: 113.8 | I14: 74.7 | J14: 206.8 | K14: 3.778 | L14: 18.5 | M14: 24 | N14: 20.19 | O14: 40991 | P14: =YEAR(O14) -> 2012 | Q14: =TEXT(O14,"mmm") -> Mar | R14: 85.828408 | S14: =IFERROR(D14*E14,"") -> 890.25721 | T14: =IF(E14="","Unknown",_xlfn.IFS(E14<15,"Budget",E14<30,"Mid-range",TRUE(),"Luxury")) -> Luxury | U14: =IF(COUNTBLANK(D14:R14)>0,"Incomplete","Complete") -> Complete | V14: =IFERROR(RANK(D14,$D$2:$D$158),"") -> 81 | W14: =IFERROR(RANK(S14,$S$2:$S$158),"") -> 61
A15: Buick | B15: LeSabre | C15: Passenger Car | D15: 83.257 | E15: 27.885 | F15: 3.8 | G15: 205 | H15: 112.2 | I15: 73.5 | J15: 200 | K15: 3.591 | L15: 17.5 | M15: 25 | N15: 13.36 | O15: 40747 | P15: =YEAR(O15) -> 2011 | Q15: =TEXT(O15,"mmm") -> Jul | R15: 84.254526 | S15: =IFERROR(D15*E15,"") -> 2321.6214 | T15: =IF(E15="","Unknown",_xlfn.IFS(E15<15,"Budget",E15<30,"Mid-range",TRUE(),"Luxury")) -> Mid-range | U15: =IF(COUNTBLANK(D15:R15)>0,"Incomplete","Complete") -> Complete | V15: =IFERROR(RANK(D15,$D$2:$D$158),"") -> 28 | W15: =IFERROR(RANK(S15,$S$2:$S$158),"") -> 17
A16: Cadillac | B16: DeVille | C16: Passenger Car | D16: 63.729 | E16: 39.895 | F16: 4.6 | G16: 275 | H16: 115.3 | I16: 74.5 | J16: 207.2 | K16: 3.978 | L16: 18.5 | M16: 22 | N16: 22.525 | O16: 40962 | P16: =YEAR(O16) -> 2012 | Q16: =TEXT(O16,"mmm") -> Feb | R16: 113.8546 | S16: =IFERROR(D16*E16,"") -> 2542.4685 | T16: =IF(E16="","Unknown",_xlfn.IFS(E16<15,"Budget",E16<30,"Mid-range",TRUE(),"Luxury")) -> Luxury | U16: =IF(COUNTBLANK(D16:R16)>0,"Incomplete","Complete") -> Complete | V16: =IFERROR(RANK(D16,$D$2:$D$158),"") -> 45 | W16: =IFERROR(RANK(S16,$S$2:$S$158),"") -> 15
A17: Cadillac | B17: Seville | C17: Passenger Car | D17: 15.943 | E17: 44.475 | F17: 4.6 | G17: 275 | H17: 112.2 | I17: 75 | J17: 201 | L17: 18.5 | M17: 22 | N17: 27.1 | O17: 40662 | P17: =YEAR(O17) -> 2011 | Q17: =TEXT(O17,"mmm") -> Apr | R17: 115.62136 | S17: =IFERROR(D17*E17,"") -> 709.06493 | T17: =IF(E17="","Unknown",_xlfn.IFS(E17<15,"Budget",E17<30,"Mid-range",TRUE(),"Luxury")) -> Luxury | U17: =IF(COUNTBLANK(D17:R17)>0,"Incomplete","Complete") -> Incomplete | V17: =IFERROR(RANK(D17,$D$2:$D$158),"") -> 112 | W17: =IFERROR(RANK(S17,$S$2:$S$158),"") -> 77
A18: Cadillac | B18: Eldorado | C18: Passenger Car | D18: 6.536 | E18: 39.665 | F18: 4.6 | G18: 275 | H18: 108 | I18: 75.5 | J18: 200.6 | K18: 3.843 | L18: 19 | M18: 22 | N18: 25.725 | O18: 40874 | P18: =YEAR(O18) -> 2011 | Q18: =TEXT(O18,"mmm") -> Nov | R18: 113.76587 | S18: =IFERROR(D18*E18,"") -> 259.25044 | T18: =IF(E18="","Unknown",_xlfn.IFS(E18<15,"Budget",E18<30,"Mid-range",TRUE(),"Luxury")) -> Luxury | U18: =IF(COUNTBLANK(D18:R18)>0,"Incomplete","Complete") -> Complete | V18: =IFERROR(RANK(D18,$D$2:$D$158),"") -> 138 | W18: =IFERROR(RANK(S18,$S$2:$S$158),"") -> 132
A19: Cadillac | B19: Catera | C19: Passenger Car | D19: 11.185 | E19: 31.01 | F19: 3 | G19: 200 | H19: 107.4 | I19: 70.3 | J19: 194.8 | K19: 3.77 | L19: 18 | M19: 22 | N19: 18.225 | O19: 40814 | P19: =YEAR(O19) -> 2011 | Q19: =TEXT(O19,"mmm") -> Sep | R19: 83.483094 | S19: =IFERROR(D19*E19,"") -> 346.84685 | T19: =IF(E19="","Unknown",_xlfn.IFS(E19<15,"Budget",E19<30,"Mid-range",TRUE(),"Luxury")) -> Luxury | U19: =IF(COUNTBLANK(D19:R19)>0,"Incomplete","Complete") -> Complete | V19: =IFERROR(RANK(D19,$D$2:$D$158),"") -> 126 | W19: =IFERROR(RANK(S19,$S$2:$S$158),"") -> 123
A20: Cadillac | B20: Escalade | C20: SUV/Truck/Van | D20: 14.785 | E20: 46.225 | F20: 5.7 | G20: 255 | H20: 117.5 | I20: 77 | J20: 201.2 | K20: 5.572 | L20: 30 | M20: 15 | O20: 41016 | P20: =YEAR(O20) -> 2012 | Q20: =TEXT(O20,"mmm") -> Apr | R20: 109.50912 | S20: =IFERROR(D20*E20,"") -> 683.43663 | T20: =IF(E20="","Unknown",_xlfn.IFS(E20<15,"Budget",E20<30,"Mid-range",TRUE(),"Luxury")) -> Luxury | U20: =IF(COUNTBLANK(D20:R20)>0,"Incomplete","Complete") -> Incomplete | V20: =IFERROR(RANK(D20,$D$2:$D$158),"") -> 115 | W20: =IFERROR(RANK(S20,$S$2:$S$158),"") -> 80
A21: Chevrolet | B21: Cavalier | C21: Passenger Car | D21: 145.519 | E21: 13.26 | F21: 2.2 | G21: 115 | H21: 104.1 | I21: 67.9 | J21: 180.9 | K21: 2.676 | L21: 14.3 | M21: 27 | N21: 9.25 | O21: 40772 | P21: =YEAR(O21) -> 2011 | Q21: =TEXT(O21,"mmm") -> Aug | R21: 46.363347 | S21: =IFERROR(D21*E21,"") -> 1929.5819 | T21: =IF(E21="","Unknown",_xlfn.IFS(E21<15,"Budget",E21<30,"Mid-range",TRUE(),"Luxury")) -> Budget | U21: =IF(COUNTBLANK(D21:R21)>0,"Incomplete","Complete") -> Complete | V21: =IFERROR(RANK(D21,$D$2:$D$158),"") -> 13 | W21: =IFERROR(RANK(S21,$S$2:$S$158),"") -> 27
A22: Chevrolet | B22: Malibu | C22: Passenger Car | D22: 135.126 | E22: 16.535 | F22: 3.1 | G22: 170 | H22: 107 | I22: 69.4 | J22: 190.4 | K22: 3.051 | L22: 15 | M22: 25 | N22: 11.225 | O22: 40987 | P22: =YEAR(O22) -> 2012 | Q22: =TEXT(O22,"mmm") -> Mar | R22: 67.314462 | S22: =IFERROR(D22*E22,"") -> 2234.3084 | T22: =IF(E22="","Unknown",_xlfn.IFS(E22<15,"Budget",E22<30,"Mid-range",TRUE(),"Luxury")) -> Mid-range | U22: =IF(COUNTBLANK(D22:R22)>0,"Incomplete","Complete") -> Complete | V22: =IFERROR(RANK(D22,$D$2:$D$158),"") -> 15 | W22: =IFERROR(RANK(S22,$S$2:$S$158),"") -> 18
A23: Chevrolet | B23: Lumina | C23: Passenger Car | D23: 24.629 | E23: 18.89 | F23: 3.1 | G23: 175 | H23: 107.5 | I23: 72.5 | J23: 200.9 | K23: 3.33 | L23: 16.6 | M23: 25 | N23: 10.31 | O23: 40687 | P23: =YEAR(O23) -> 2011 | Q23: =TEXT(O23,"mmm") -> May | R23: 69.991396 | S23: =IFERROR(D23*E23,"") -> 465.24181 | T23: =IF(E23="","Unknown",_xlfn.IFS(E23<15,"Budget",E23<30,"Mid-range",TRUE(),"Luxury")) -> Mid-range | U23: =IF(COUNTBLANK(D23:R23)>0,"Incomplete","Complete") -> Complete | V23: =IFERROR(RANK(D23,$D$2:$D$158),"") -> 89 | W23: =IFERROR(RANK(S23,$S$2:$S$158),"") -> 105
A24: Chevrolet | B24: Monte Carlo | C24: Passenger Car | D24: 42.593 | E24: 19.39 | F24: 3.4 | G24: 180 | H24: 110.5 | I24: 72.7 | J24: 197.9 | K24: 3.34 | L24: 17 | M24: 27 | N24: 11.525 | O24: 40899 | P24: =YEAR(O24) -> 2011 | Q24: =TEXT(O24,"mmm") -> Dec | R24: 72.030917 | S24: =IFERROR(D24*E24,"") -> 825.87827 | T24: =IF(E24="","Unknown",_xlfn.IFS(E24<15,"Budget",E24<30,"Mid-range",TRUE(),"Luxury")) -> Mid-range | U24: =IF(COUNTBLANK(D24:R24)>0,"Incomplete","Complete") -> Complete | V24: =IFERROR(RANK(D24,$D$2:$D$158),"") -> 59 | W24: =IFERROR(RANK(S24,$S$2:$S$158),"") -> 66
A25: Chevrolet | B25: Camaro | C25: Passenger Car | D25: 26.402 | E25: 24.34 | F25: 3.8 | G25: 200 | H25: 101.1 | I25: 74.1 | J25: 193.2 | K25: 3.5 | L25: 16.8 | M25: 25 | N25: 13.025 | O25: 40839 | P25: =YEAR(O25) -> 2011 | Q25: =TEXT(O25,"mmm") -> Oct | R25: 81.118543 | S25: =IFERROR(D25*E25,"") -> 642.62468 | T25: =IF(E25="","Unknown",_xlfn.IFS(E25<15,"Budget",E25<30,"Mid-range",TRUE(),"Luxury")) -> Mid-range | U25: =IF(COUNTBLANK(D25:R25)>0,"Incomplete","Complete") -> Complete | V25: =IFERROR(RANK(D25,$D$2:$D$158),"") -> 86 | W25: =IFERROR(RANK(S25,$S$2:$S$158),"") -> 85
A26: Chevrolet | B26: Corvette | C26: Passenger Car | D26: 17.947 | E26: 45.705 | F26: 5.7 | G26: 345 | H26: 104.5 | I26: 73.6 | J26: 179.7 | K26: 3.21 | L26: 19.1 | M26: 22 | N26: 36.225 | O26: 41041 | P26: =YEAR(O26) -> 2012 | Q26: =TEXT(O26,"mmm") -> May | R26: 141.14115 | S26: =IFERROR(D26*E26,"") -> 820.26763 | T26: =IF(E26="","Unknown",_xlfn.IFS(E26<15,"Budget",E26<30,"Mid-range",TRUE(),"Luxury")) -> Luxury | U26: =IF(COUNTBLANK(D26:R26)>0,"Incomplete","Complete") -> Complete | V26: =IFERROR(RANK(D26,$D$2:$D$158),"") -> 105 | W26: =IFERROR(RANK(S26,$S$2:$S$158),"") -> 67
A27: Chevrolet | B27: Prizm | C27: Passenger Car | D27: 32.299 | E27: 13.96 | F27: 1.8 | G27: 120 | H27: 97.1 | I27: 66.7 | J27: 174.3 | K27: 2.398 | L27: 13.2 | M27: 33 | N27: 9.125 | O27: 40797 | P27: =YEAR(O27) -> 2011 | Q27: =TEXT(O27,"mmm") -> Sep | R27: 48.297636 | S27: =IFERROR(D27*E27,"") -> 450.89404 | T27: =IF(E27="","Unknown",_xlfn.IFS(E27<15,"Budget",E27<30,"Mid-range",TRUE(),"Luxury")) -> Budget | U27: =IF(COUNTBLANK(D27:R27)>0,"Incomplete","Complete") -> Complete | V27: =IFERROR(RANK(D27,$D$2:$D$158),"") -> 75 | W27: =IFERROR(RANK(S27,$S$2:$S$158),"") -> 108
A28: Chevrolet | B28: Metro | C28: Passenger Car | D28: 21.855 | E28: 9.235 | F28: 1 | G28: 55 | H28: 93.1 | I28: 62.6 | J28: 149.4 | K28: 1.895 | L28: 10.3 | M28: 45 | N28: 5.16 | O28: 41012 | P28: =YEAR(O28) -> 2012 | Q28: =TEXT(O28,"mmm") -> Apr | R28: 23.276272 | S28: =IFERROR(D28*E28,"") -> 201.83092 | T28: =IF(E28="","Unknown",_xlfn.IFS(E28<15,"Budget",E28<30,"Mid-range",TRUE(),"Luxury")) -> Budget | U28: =IF(COUNTBLANK(D28:R28)>0,"Incomplete","Complete") -> Complete | V28: =IFERROR(RANK(D28,$D$2:$D$158),"") -> 96 | W28: =IFERROR(RANK(S28,$S$2:$S$158),"") -> 134
A29: Chevrolet | B29: Impala | C29: Passenger Car | D29: 107.995 | E29: 18.89 | F29: 3.4 | G29: 180 | H29: 110.5 | I29: 73 | J29: 200 | K29: 3.389 | L29: 17 | M29: 27 | O29: 40712 | P29: =YEAR(O29) -> 2011 | Q29: =TEXT(O29,"mmm") -> Jun | R29: 71.838039 | S29: =IFERROR(D29*E29,"") -> 2040.0256 | T29: =IF(E29="","Unknown",_xlfn.IFS(E29<15,"Budget",E29<30,"Mid-range",TRUE(),"Luxury")) -> Mid-range | U29: =IF(COUNTBLANK(D29:R29)>0,"Incomplete","Complete") -> Incomplete | V29: =IFERROR(RANK(D29,$D$2:$D$158),"") -> 20 | W29: =IFERROR(RANK(S29,$S$2:$S$158),"") -> 22
A30: Chrysler | B30: Sebring Coupe | C30: Passenger Car | D30: 7.854 | E30: 19.84 | F30: 2.5 | G30: 163 | H30: 103.7 | I30: 69.7 | J30: 190.9 | K30: 2.967 | L30: 15.9 | M30: 24 | N30: 12.36 | O30: 40924 | P30: =YEAR(O30) -> 2012 | Q30: =TEXT(O30,"mmm") -> Jan | R30: 65.957184 | S30: =IFERROR(D30*E30,"") -> 155.82336 | T30: =IF(E30="","Unknown",_xlfn.IFS(E30<15,"Budget",E30<30,"Mid-range",TRUE(),"Luxury")) -> Mid-range | U30: =IF(COUNTBLANK(D30:R30)>0,"Incomplete","Complete") -> Complete | V30: =IFERROR(RANK(D30,$D$2:$D$158),"") -> 137 | W30: =IFERROR(RANK(S30,$S$2:$S$158),"") -> 138
A31: Chrysler | B31: Sebring Conv. | C31: Passenger Car | D31: 32.775 | E31: 24.495 | F31: 2.5 | G31: 168 | H31: 106 | I31: 69.2 | J31: 193 | K31: 3.332 | L31: 16 | M31: 24 | N31: 14.18 | O31: 40864 | P31: =YEAR(O31) -> 2011 | Q31: =TEXT(O31,"mmm") -> Nov | R31: 69.521355 | S31: =IFERROR(D31*E31,"") -> 802.82362 | T31: =IF(E31="","Unknown",_xlfn.IFS(E31<15,"Budget",E31<30,"Mid-range",TRUE(),"Luxury")) -> Mid-range | U31: =IF(COUNTBLANK(D31:R31)>0,"Incomplete","Complete") -> Complete | V31: =IFERROR(RANK(D31,$D$2:$D$158),"") -> 72 | W31: =IFERROR(RANK(S31,$S$2:$S$158),"") -> 70
A32: Chrysler | B32: Concorde | C32: Passenger Car | D32: 31.148 | E32: 22.245 | F32: 2.7 | G32: 200 | H32: 113 | I32: 74.4 | J32: 209.1 | K32: 3.452 | L32: 17 | M32: 26 | N32: 13.725 | O32: 41066 | P32: =YEAR(O32) -> 2012 | Q32: =TEXT(O32,"mmm") -> Jun | R32: 80.023782 | S32: =IFERROR(D32*E32,"") -> 692.88726 | T32: =IF(E32="","Unknown",_xlfn.IFS(E32<15,"Budget",E32<30,"Mid-range",TRUE(),"Luxury")) -> Mid-range | U32: =IF(COUNTBLANK(D32:R32)>0,"Incomplete","Complete") -> Complete | V32: =IFERROR(RANK(D32,$D$2:$D$158),"") -> 76 | W32: =IFERROR(RANK(S32,$S$2:$S$158),"") -> 79
A33: Chrysler | B33: Cirrus | C33: Passenger Car | D33: 32.306 | E33: 16.48 | F33: 2 | G33: 132 | H33: 108 | I33: 71 | J33: 186 | K33: 2.911 | L33: 16 | M33: 27 | N33: 12.64 | O33: 40822 | P33: =YEAR(O33) -> 2011 | Q33: =TEXT(O33,"mmm") -> Oct | R33: 53.5662 | S33: =IFERROR(D33*E33,"") -> 532.40288 | T33: =IF(E33="","Unknown",_xlfn.IFS(E33<15,"Budget",E33<30,"Mid-range",TRUE(),"Luxury")) -> Mid-range | U33: =IF(COUNTBLANK(D33:R33)>0,"Incomplete","Complete") -> Complete | V33: =IFERROR(RANK(D33,$D$2:$D$158),"") -> 74 | W33: =IFERROR(RANK(S33,$S$2:$S$158),"") -> 97
A34: Chrysler | B34: LHS | C34: Passenger Car | D34: 13.462 | E34: 28.34 | F34: 3.5 | G34: 253 | H34: 113 | I34: 74.4 | J34: 207.7 | K34: 3.564 | L34: 17 | M34: 23 | N34: 17.325 | O34: 41037 | P34: =YEAR(O34) -> 2012 | Q34: =TEXT(O34,"mmm") -> May | R34: 101.32928 | S34: =IFERROR(D34*E34,"") -> 381.51308 | T34: =IF(E34="","Unknown",_xlfn.IFS(E34<15,"Budget",E34<30,"Mid-range",TRUE(),"Luxury")) -> Mid-range | U34: =IF(COUNTBLANK(D34:R34)>0,"Incomplete","Complete") -> Complete | V34: =IFERROR(RANK(D34,$D$2:$D$158),"") -> 120 | W34: =IFERROR(RANK(S34,$S$2:$S$158),"") -> 116
A35: Chrysler | B35: Town & Country | C35: SUV/Truck/Van | D35: 53.48 | N35: 19.54 | O35: 40737 | P35: =YEAR(O35) -> 2011 | Q35: =TEXT(O35,"mmm") -> Jul | S35: =IFERROR(D35*E35,"") -> 0 | T35: =IF(E35="","Unknown",_xlfn.IFS(E35<15,"Budget",E35<30,"Mid-range",TRUE(),"Luxury")) -> Unknown | U35: =IF(COUNTBLANK(D35:R35)>0,"Incomplete","Complete") -> Incomplete | V35: =IFERROR(RANK(D35,$D$2:$D$158),"") -> 50 | W35: =IFERROR(RANK(S35,$S$2:$S$158),"") -> 156
A36: Chrysler | B36: 300M | C36: Passenger Car | D36: 30.696 | E36: 29.185 | F36: 3.5 | G36: 253 | H36: 113 | I36: 74.4 | J36: 197.8 | K36: 3.567 | L36: 17 | M36: 23 | O36: 40949 | P36: =YEAR(O36) -> 2012 | Q36: =TEXT(O36,"mmm") -> Feb | R36: 101.65524 | S36: =IFERROR(D36*E36,"") -> 895.86276 | T36: =IF(E36="","Unknown",_xlfn.IFS(E36<15,"Budget",E36<30,"Mid-range",TRUE(),"Luxury")) -> Mid-range | U36: =IF(COUNTBLANK(D36:R36)>0,"Incomplete","Complete") -> Incomplete | V36: =IFERROR(RANK(D36,$D$2:$D$158),"") -> 78 | W36: =IFERROR(RANK(S36,$S$2:$S$158),"") -> 60
A37: Dodge | B37: Neon | C37: Passenger Car | D37: 76.034 | E37: 12.64 | F37: 2 | G37: 132 | H37: 105 | I37: 74.4 | J37: 174.4 | K37: 2.567 | L37: 12.5 | M37: 29 | N37: 7.75 | O37: 40889 | P37: =YEAR(O37) -> 2011 | Q37: =TEXT(O37,"mmm") -> Dec | R37: 52.084899 | S37: =IFERROR(D37*E37,"") -> 961.06976 | T37: =IF(E37="","Unknown",_xlfn.IFS(E37<15,"Budget",E37<30,"Mid-range",TRUE(),"Luxury")) -> Budget | U37: =IF(COUNTBLANK(D37:R37)>0,"Incomplete","Complete") -> Complete | V37: =IFERROR(RANK(D37,$D$2:$D$158),"") -> 34 | W37: =IFERROR(RANK(S37,$S$2:$S$158),"") -> 58
A38: Dodge | B38: Avenger | C38: Passenger Car | D38: 4.734 | E38: 19.045 | F38: 2.5 | G38: 163 | H38: 103.7 | I38: 69.1 | J38: 190.2 | K38: 2.879 | L38: 15.9 | M38: 24 | N38: 12.545 | O38: 41091 | P38: =YEAR(O38) -> 2012 | Q38: =TEXT(O38,"mmm") -> Jul | R38: 65.650508 | S38: =IFERROR(D38*E38,"") -> 90.15903 | T38: =IF(E38="","Unknown",_xlfn.IFS(E38<15,"Budget",E38<30,"Mid-range",TRUE(),"Luxury")) -> Mid-range | U38: =IF(COUNTBLANK(D38:R38)>0,"Incomplete","Complete") -> Complete | V38: =IFERROR(RANK(D38,$D$2:$D$158),"") -> 144 | W38: =IFERROR(RANK(S38,$S$2:$S$158),"") -> 145
A39: Dodge | B39: Stratus | C39: Passenger Car | D39: 71.186 | E39: 20.23 | F39: 2.5 | G39: 168 | H39: 108 | I39: 71 | J39: 186 | K39: 3.058 | L39: 16 | M39: 24 | N39: 10.185 | O39: 40847 | P39: =YEAR(O39) -> 2011 | Q39: =TEXT(O39,"mmm") -> Oct | R39: 67.876108 | S39: =IFERROR(D39*E39,"") -> 1440.0928 | T39: =IF(E39="","Unknown",_xlfn.IFS(E39<15,"Budget",E39<30,"Mid-range",TRUE(),"Luxury")) -> Mid-range | U39: =IF(COUNTBLANK(D39:R39)>0,"Incomplete","Complete") -> Complete | V39: =IFERROR(RANK(D39,$D$2:$D$158),"") -> 37 | W39: =IFERROR(RANK(S39,$S$2:$S$158),"") -> 39
A40: Dodge | B40: Intrepid | C40: Passenger Car | D40: 88.028 | E40: 22.505 | F40: 2.7 | G40: 202 | H40: 113 | I40: 74.7 | J40: 203.7 | K40: 3.489 | L40: 17 | N40: 12.275 | O40: 41062 | P40: =YEAR(O40) -> 2012 | Q40: =TEXT(O40,"mmm") -> Jun | R40: 80.83147 | S40: =IFERROR(D40*E40,"") -> 1981.0701 | T40: =IF(E40="","Unknown",_xlfn.IFS(E40<15,"Budget",E40<30,"Mid-range",TRUE(),"Luxury")) -> Mid-range | U40: =IF(COUNTBLANK(D40:R40)>0,"Incomplete","Complete") -> Incomplete | V40: =IFERROR(RANK(D40,$D$2:$D$158),"") -> 25 | W40: =IFERROR(RANK(S40,$S$2:$S$158),"") -> 25
...

Sheet Dashboard
B2: CAR SALES ANALYSIS DASHBOARD
B5: Filter by Brand: | D5: All Brands
B7: Total Cars Sold (units) | D7: Total Sales Revenue ($M) | F7: Average Car Price ($000) | H7: Highest Car Price ($000) | J7: Avg Units Sold per Model (000s)* | L7: Total Brands
B8: =IF($D$5="All Brands",SUM('Cleaned Data'!$D:$D),SUMIFS('Cleaned Data'!$D:$D,'Cleaned Data'!$A:$A,$D$5))*1000 -> 8320698 | D8: =IF($D$5="All Brands",SUM('Cleaned Data'!$S:$S),SUMIFS('Cleaned Data'!$S:$S,'Cleaned Data'!$A:$A,$D$5)) -> 179992.3 | F8: =IF($D$5="All Brands",AVERAGE('Cleaned Data'!$E:$E),AVERAGEIFS('Cleaned Data'!$E:$E,'Cleaned Data'!$A:$A,$D$5)) -> 27.390755 | H8: =IF($D$5="All Brands",MAX('Cleaned Data'!$E:$E),_xlfn.MAXIFS('Cleaned Data'!$E:$E,'Cleaned Data'!$A:$A,$D$5)) -> 85.5 | J8: =IF($D$5="All Brands",AVERAGE('Cleaned Data'!$D:$D),AVERAGEIFS('Cleaned Data'!$D:$D,'Cleaned Data'!$A:$A,$D$5)) -> 52.998076 | L8: =IF($D$5="All Brands",SUMPRODUCT(1/COUNTIF('Cleaned Data'!$A$2:$A$158,'Cleaned Data'!$A$2:$A$158)),1) -> 30

Sheet Analysis
B2: Analysis — Pivot-Style Summary Tables
B4: Brand Summary
B5: Brand | C5: Total Units Sold | D5: Total Revenue ($M) | E5: Avg Price ($) | F5: Number of Models | G5: Avg Resale Value ($) | H5: Revenue Rank
B6: Acura | C6: =SUMIFS('Cleaned Data'!$D:$D,'Cleaned Data'!$A:$A,$B6) -> 79.005 | D6: =SUMIFS('Cleaned Data'!$S:$S,'Cleaned Data'!$A:$A,$B6) -> 1842.9601 | E6: =IFERROR(AVERAGEIFS('Cleaned Data'!$E:$E,'Cleaned Data'!$A:$A,$B6),0) -> 30.633333 | F6: =COUNTIFS('Cleaned Data'!$A:$A,$B6) -> 4 | G6: =IFERROR(AVERAGEIFS('Cleaned Data'!$N:$N,'Cleaned Data'!$A:$A,$B6),0) -> 21.04625 | H6: =RANK(D6,$D$6:$D$35) -> 21
B7: Audi | C7: =SUMIFS('Cleaned Data'!$D:$D,'Cleaned Data'!$A:$A,$B7) -> 40.557 | D7: =SUMIFS('Cleaned Data'!$S:$S,'Cleaned Data'!$A:$A,$B7) -> 1212.465 | E7: =IFERROR(AVERAGEIFS('Cleaned Data'!$E:$E,'Cleaned Data'!$A:$A,$B7),0) -> 39.98 | F7: =COUNTIFS('Cleaned Data'!$A:$A,$B7) -> 3 | G7: =IFERROR(AVERAGEIFS('Cleaned Data'!$N:$N,'Cleaned Data'!$A:$A,$B7),0) -> 28.27 | H7: =RANK(D7,$D$6:$D$35) -> 25
B8: BMW | C8: =SUMIFS('Cleaned Data'!$D:$D,'Cleaned Data'!$A:$A,$B8) -> 46.505 | D8: =SUMIFS('Cleaned Data'!$S:$S,'Cleaned Data'!$A:$A,$B8) -> 1523.0872 | E8: =IFERROR(AVERAGEIFS('Cleaned Data'!$E:$E,'Cleaned Data'!$A:$A,$B8),0) -> 33.096667 | F8: =COUNTIFS('Cleaned Data'!$A:$A,$B8) -> 3 | G8: =IFERROR(AVERAGEIFS('Cleaned Data'!$N:$N,'Cleaned Data'!$A:$A,$B8),0) -> 32.4 | H8: =RANK(D8,$D$6:$D$35) -> 24
B9: Buick | C9: =SUMIFS('Cleaned Data'!$D:$D,'Cleaned Data'!$A:$A,$B9) -> 242.019 | D9: =SUMIFS('Cleaned Data'!$S:$S,'Cleaned Data'!$A:$A,$B9) -> 6219.4866 | E9: =IFERROR(AVERAGEIFS('Cleaned Data'!$E:$E,'Cleaned Data'!$A:$A,$B9),0) -> 26.78125 | F9: =COUNTIFS('Cleaned Data'!$A:$A,$B9) -> 4 | G9: =IFERROR(AVERAGEIFS('Cleaned Data'!$N:$N,'Cleaned Data'!$A:$A,$B9),0) -> 14.94125 | H9: =RANK(D9,$D$6:$D$35) -> 9
B10: Cadillac | C10: =SUMIFS('Cleaned Data'!$D:$D,'Cleaned Data'!$A:$A,$B10) -> 112.178 | D10: =SUMIFS('Cleaned Data'!$S:$S,'Cleaned Data'!$A:$A,$B10) -> 4541.0673 | E10: =IFERROR(AVERAGEIFS('Cleaned Data'!$E:$E,'Cleaned Data'!$A:$A,$B10),0) -> 40.254 | F10: =COUNTIFS('Cleaned Data'!$A:$A,$B10) -> 5 | G10: =IFERROR(AVERAGEIFS('Cleaned Data'!$N:$N,'Cleaned Data'!$A:$A,$B10),0) -> 23.39375 | H10: =RANK(D10,$D$6:$D$35) -> 12
B11: Chevrolet | C11: =SUMIFS('Cleaned Data'!$D:$D,'Cleaned Data'!$A:$A,$B11) -> 554.365 | D11: =SUMIFS('Cleaned Data'!$S:$S,'Cleaned Data'!$A:$A,$B11) -> 9610.6533 | E11: =IFERROR(AVERAGEIFS('Cleaned Data'!$E:$E,'Cleaned Data'!$A:$A,$B11),0) -> 20.022778 | F11: =COUNTIFS('Cleaned Data'!$A:$A,$B11) -> 9 | G11: =IFERROR(AVERAGEIFS('Cleaned Data'!$N:$N,'Cleaned Data'!$A:$A,$B11),0) -> 13.230625 | H11: =RANK(D11,$D$6:$D$35) -> 5
B12: Chrysler | C12: =SUMIFS('Cleaned Data'!$D:$D,'Cleaned Data'!$A:$A,$B12) -> 201.721 | D12: =SUMIFS('Cleaned Data'!$S:$S,'Cleaned Data'!$A:$A,$B12) -> 3461.313 | E12: =IFERROR(AVERAGEIFS('Cleaned Data'!$E:$E,'Cleaned Data'!$A:$A,$B12),0) -> 23.430833 | F12: =COUNTIFS('Cleaned Data'!$A:$A,$B12) -> 7 | G12: =IFERROR(AVERAGEIFS('Cleaned Data'!$N:$N,'Cleaned Data'!$A:$A,$B12),0) -> 14.961667 | H12: =RANK(D12,$D$6:$D$35) -> 18
B13: Dodge | C13: =SUMIFS('Cleaned Data'!$D:$D,'Cleaned Data'!$A:$A,$B13) -> 910.149 | D13: =SUMIFS('Cleaned Data'!$S:$S,'Cleaned Data'!$A:$A,$B13) -> 18000.608 | E13: =IFERROR(AVERAGEIFS('Cleaned Data'!$E:$E,'Cleaned Data'!$A:$A,$B13),0) -> 24.213636 | F13: =COUNTIFS('Cleaned Data'!$A:$A,$B13) -> 11 | G13: =IFERROR(AVERAGEIFS('Cleaned Data'!$N:$N,'Cleaned Data'!$A:$A,$B13),0) -> 16.8505 | H13: =RANK(D13,$D$6:$D$35) -> 2
B14: Ford | C14: =SUMIFS('Cleaned Data'!$D:$D,'Cleaned Data'!$A:$A,$B14) -> 2022.635 | D14: =SUMIFS('Cleaned Data'!$S:$S,'Cleaned Data'!$A:$A,$B14) -> 45776.129 | E14: =IFERROR(AVERAGEIFS('Cleaned Data'!$E:$E,'Cleaned Data'!$A:$A,$B14),0) -> 21.047273 | F14: =COUNTIFS('Cleaned Data'!$A:$A,$B14) -> 11 | G14: =IFERROR(AVERAGEIFS('Cleaned Data'!$N:$N,'Cleaned Data'!$A:$A,$B14),0) -> 12.96 | H14: =RANK(D14,$D$6:$D$35) -> 1
B15: Honda | C15: =SUMIFS('Cleaned Data'!$D:$D,'Cleaned Data'!$A:$A,$B15) -> 592.674 | D15: =SUMIFS('Cleaned Data'!$S:$S,'Cleaned Data'!$A:$A,$B15) -> 9940.3056 | E15: =IFERROR(AVERAGEIFS('Cleaned Data'!$E:$E,'Cleaned Data'!$A:$A,$B15),0) -> 20.277 | F15: =COUNTIFS('Cleaned Data'!$A:$A,$B15) -> 5 | G15: =IFERROR(AVERAGEIFS('Cleaned Data'!$N:$N,'Cleaned Data'!$A:$A,$B15),0) -> 15.557 | H15: =RANK(D15,$D$6:$D$35) -> 4
B16: Hyundai | C16: =SUMIFS('Cleaned Data'!$D:$D,'Cleaned Data'!$A:$A,$B16) -> 137.326 | D16: =SUMIFS('Cleaned Data'!$S:$S,'Cleaned Data'!$A:$A,$B16) -> 1628.0631 | E16: =IFERROR(AVERAGEIFS('Cleaned Data'!$E:$E,'Cleaned Data'!$A:$A,$B16),0) -> 12.165667 | F16: =COUNTIFS('Cleaned Data'!$A:$A,$B16) -> 3 | G16: =IFERROR(AVERAGEIFS('Cleaned Data'!$N:$N,'Cleaned Data'!$A:$A,$B16),0) -> 7.5316667 | H16: =RANK(D16,$D$6:$D$35) -> 23
B17: Infiniti | C17: =SUMIFS('Cleaned Data'!$D:$D,'Cleaned Data'!$A:$A,$B17) -> 23.713 | D17: =SUMIFS('Cleaned Data'!$S:$S,'Cleaned Data'!$A:$A,$B17) -> 698.70355 | E17: =IFERROR(AVERAGEIFS('Cleaned Data'!$E:$E,'Cleaned Data'!$A:$A,$B17),0) -> 29.465 | F17: =COUNTIFS('Cleaned Data'!$A:$A,$B17) -> 1 | G17: =IFERROR(AVERAGEIFS('Cleaned Data'!$N:$N,'Cleaned Data'!$A:$A,$B17),0) -> 19.69 | H17: =RANK(D17,$D$6:$D$35) -> 27
... B35: Volvo | C35: =SUMIFS('Cleaned Data'!$D:$D,'Cleaned Data'!$A:$A,$B35) -> 75.74 | D35: =SUMIFS('Cleaned Data'!$S:$S,'Cleaned Data'!$A:$A,$B35) -> 2249.2376 | E35: =IFERROR(AVERAGEIFS('Cleaned Data'!$E:$E,'Cleaned Data'!$A:$A,$B35),0) -> 30.933333 | F35: =COUNTIFS('Cleaned Data'!$A:$A,$B35) -> 6 | G35: =IFERROR(AVERAGEIFS('Cleaned Data'!$N:$N,'Cleaned Data'!$A:$A,$B35),0) -> 0 | H35: =RANK(D35,$D$6:$D$35) -> 19
B38: Vehicle Segment Summary
B39: Segment | C39: Total Units Sold | D39: Total Revenue ($M) | E39: Avg Price ($) | F39: Number of Models
B40: Passenger Car | C40: =SUMIFS('Cleaned Data'!$D:$D,'Cleaned Data'!$C:$C,$B40) -> 5015.184 | D40: =SUMIFS('Cleaned Data'!$S:$S,'Cleaned Data'!$C:$C,$B40) -> 101911.22 | E40: =IFERROR(AVERAGEIFS('Cleaned Data'!$E:$E,'Cleaned Data'!$C:$C,$B40),0) -> 27.7632 | F40: =COUNTIFS('Cleaned Data'!$C:$C,$B40) -> 116
B41: SUV/Truck/Van | C41: =SUMIFS('Cleaned Data'!$D:$D,'Cleaned Data'!$C:$C,$B41) -> 3305.514 | D41: =SUMIFS('Cleaned Data'!$S:$S,'Cleaned Data'!$C:$C,$B41) -> 78081.079 | E41: =IFERROR(AVERAGEIFS('Cleaned Data'!$E:$E,'Cleaned Data'!$C:$C,$B41),0) -> 26.319975 | F41: =COUNTIFS('Cleaned Data'!$C:$C,$B41) -> 41
B43: Price Tier Summary
B44: Price Tier | C44: Total Units Sold | D44: Total Revenue ($M) | E44: Avg Price ($) | F44: Number of Models
B45: Budget | C45: =SUMIFS('Cleaned Data'!$D:$D,'Cleaned Data'!$T:$T,$B45) -> 1583.203 | D45: =SUMIFS('Cleaned Data'!$S:$S,'Cleaned Data'!$T:$T,$B45) -> 19800.774 | E45: =IFERROR(AVERAGEIFS('Cleaned Data'!$E:$E,'Cleaned Data'!$T:$T,$B45),0) -> 12.692571 | F45: =COUNTIFS('Cleaned Data'!$T:$T,$B45) -> 21
B46: Mid-range | C46: =SUMIFS('Cleaned Data'!$D:$D,'Cleaned Data'!$T:$T,$B46) -> 5626.817 | D46: =SUMIFS('Cleaned Data'!$S:$S,'Cleaned Data'!$T:$T,$B46) -> 120851.33 | E46: =IFERROR(AVERAGEIFS('Cleaned Data'!$E:$E,'Cleaned Data'!$T:$T,$B46),0) -> 21.878551 | F46: =COUNTIFS('Cleaned Data'!$T:$T,$B46) -> 89
B47: Luxury | C47: =SUMIFS('Cleaned Data'!$D:$D,'Cleaned Data'!$T:$T,$B47) -> 1043.084 | D47: =SUMIFS('Cleaned Data'!$S:$S,'Cleaned Data'!$T:$T,$B47) -> 39340.19 | E47: =IFERROR(AVERAGEIFS('Cleaned Data'!$E:$E,'Cleaned Data'!$T:$T,$B47),0) -> 45.151822 | F47: =COUNTIFS('Cleaned Data'!$T:$T,$B47) -> 45
B49: Sales by Launch Year (substitute for Monthly Sales — no per-month sales data exists)
B50: Launch Year | C50: Total Units Sold | D50: Total Revenue ($M) | E50: Number of Models
B51: 2008 | C51: =SUMIFS('Cleaned Data'!$D:$D,'Cleaned Data'!$P:$P,$B51) -> 27.609 | D51: =SUMIFS('Cleaned Data'!$S:$S,'Cleaned Data'!$P:$P,$B51) -> 760.90404 | E51: =COUNTIFS('Cleaned Data'!$P:$P,$B51) -> 1
B52: 2009 | C52: =SUMIFS('Cleaned Data'!$D:$D,'Cleaned Data'!$P:$P,$B52) -> 100.635 | D52: =SUMIFS('Cleaned Data'!$S:$S,'Cleaned Data'!$P:$P,$B52) -> 1925.0126 | E52: =COUNTIFS('Cleaned Data'!$P:$P,$B52) -> 2
B53: 2011 | C53: =SUMIFS('Cleaned Data'!$D:$D,'Cleaned Data'!$P:$P,$B53) -> 3717.405 | D53: =SUMIFS('Cleaned Data'!$S:$S,'Cleaned Data'!$P:$P,$B53) -> 75978.509 | E53: =COUNTIFS('Cleaned Data'!$P:$P,$B53) -> 79
B54: 2012 | C54: =SUMIFS('Cleaned Data'!$D:$D,'Cleaned Data'!$P:$P,$B54) -> 4475.049 | D54: =SUMIFS('Cleaned Data'!$S:$S,'Cleaned Data'!$P:$P,$B54) -> 101327.87 | E54: =COUNTIFS('Cleaned Data'!$P:$P,$B54) -> 75
B56: Top 10 Best-Selling Models
B57: Rank | C57: Model | D57: Manufacturer | E57: Units Sold | F57: Revenue ($M)
B58: 1 | C58: =INDEX('Cleaned Data'!$B:$B,MATCH(LARGE('Cleaned Data'!$D$2:$D$158,1),'Cleaned Data'!$D:$D,0)) -> F-Series | D58: =INDEX('Cleaned Data'!$A:$A,MATCH(LARGE('Cleaned Data'!$D$2:$D$158,1),'Cleaned Data'!$D:$D,0)) -> Ford | E58: =LARGE('Cleaned Data'!$D$2:$D$158,1) -> 540.561 | F58: =INDEX('Cleaned Data'!$S:$S,MATCH(LARGE('Cleaned Data'!$D$2:$D$158,1),'Cleaned Data'!$D:$D,0)) -> 14560.011
B59: 2 | C59: =INDEX('Cleaned Data'!$B:$B,MATCH(LARGE('Cleaned Data'!$D$2:$D$158,2),'Cleaned Data'!$D:$D,0)) -> Explorer | D59: =INDEX('Cleaned Data'!$A:$A,MATCH(LARGE('Cleaned Data'!$D$2:$D$158,2),'Cleaned Data'!$D:$D,0)) -> Ford | E59: =LARGE('Cleaned Data'!$D$2:$D$158,2) -> 276.747 | F59: =INDEX('Cleaned Data'!$S:$S,MATCH(LARGE('Cleaned Data'!$D$2:$D$158,2),'Cleaned Data'!$D:$D,0)) -> 8836.5317
B60: 3 | C60: =INDEX('Cleaned Data'!$B:$B,MATCH(LARGE('Cleaned Data'!$D$2:$D$158,3),'Cleaned Data'!$D:$D,0)) -> Camry | D60: =INDEX('Cleaned Data'!$A:$A,MATCH(LARGE('Cleaned Data'!$D$2:$D$158,3),'Cleaned Data'!$D:$D,0)) -> Toyota | E60: =LARGE('Cleaned Data'!$D$2:$D$158,3) -> 247.994 | F60: =INDEX('Cleaned Data'!$S:$S,MATCH(LARGE('Cleaned Data'!$D$2:$D$158,3),'Cleaned Data'!$D:$D,0)) -> 4344.3589
B61: 4 | C61: =INDEX('Cleaned Data'!$B:$B,MATCH(LARGE('Cleaned Data'!$D$2:$D$158,4),'Cleaned Data'!$D:$D,0)) -> Taurus | D61: =INDEX('Cleaned Data'!$A:$A,MATCH(LARGE('Cleaned Data'!$D$2:$D$158,4),'Cleaned Data'!$D:$D,0)) -> Ford | E61: =LARGE('Cleaned Data'!$D$2:$D$158,4) -> 245.815 | F61: =INDEX('Cleaned Data'!$S:$S,MATCH(LARGE('Cleaned Data'!$D$2:$D$158,4),'Cleaned Data'!$D:$D,0)) -> 4396.4013
B62: 5 | C62: =INDEX('Cleaned Data'!$B:$B,MATCH(LARGE('Cleaned Data'!$D$2:$D$158,5),'Cleaned Data'!$D:$D,0)) -> Accord | D62: =INDEX('Cleaned Data'!$A:$A,MATCH(LARGE('Cleaned Data'!$D$2:$D$158,5),'Cleaned Data'!$D:$D,0)) -> Honda | E62: =LARGE('Cleaned Data'!$D$2:$D$158,5) -> 230.902 | F62: =INDEX('Cleaned Data'!$S:$S,MATCH(LARGE('Cleaned Data'!$D$2:$D$158,5),'Cleaned Data'!$D:$D,0)) -> 3544.3457
B63: 6 | C63: =INDEX('Cleaned Data'!$B:$B,MATCH(LARGE('Cleaned Data'!$D$2:$D$158,6),'Cleaned Data'!$D:$D,0)) -> Ram Pickup | D63: =INDEX('Cleaned Data'!$A:$A,MATCH(LARGE('Cleaned Data'!$D$2:$D$158,6),'Cleaned Data'!$D:$D,0)) -> Dodge | E63: =LARGE('Cleaned Data'!$D$2:$D$158,6) -> 227.061 | F63: =INDEX('Cleaned Data'!$S:$S,MATCH(LARGE('Cleaned Data'!$D$2:$D$158,6),'Cleaned Data'!$D:$D,0)) -> 4418.6071
B64: 7 | C64: =INDEX('Cleaned Data'!$B:$B,MATCH(LARGE('Cleaned Data'!$D$2:$D$158,7),'Cleaned Data'!$D:$D,0)) -> Ranger | D64: =INDEX('Cleaned Data'!$A:$A,MATCH(LARGE('Cleaned Data'!$D$2:$D$158,7),'Cleaned Data'!$D:$D,0)) -> Ford | E64: =LARGE('Cleaned Data'!$D$2:$D$158,7) -> 220.65 | F64: =INDEX('Cleaned Data'!$S:$S,MATCH(LARGE('Cleaned Data'!$D$2:$D$158,7),'Cleaned Data'!$D:$D,0)) -> 2658.8325
...

Sheet Lookup
BI1: Acura | BJ1: {=_xlfn.UNIQUE(BI1:BI157)} -> Acura
B2: Model Lookup Tool | BI2: Acura | BJ2: Audi
BI3: Acura | BJ3: BMW
BI4: Acura | BJ4: Buick
B5: Search Model: | C5: GTI | BI5: Audi | BJ5: Cadillac
BI6: Audi | BJ6: Chevrolet
B7: Manufacturer | C7: =IFERROR(INDEX('Cleaned Data'!A:A,MATCH($C$5,'Cleaned Data'!B:B,0)),"Model not found") -> Volkswagen | BI7: Audi | BJ7: Chrysler
B8: Price, $ (VLOOKUP) | C8: =IFERROR(VLOOKUP($C$5,'Cleaned Data'!B:E,4,FALSE()),"Model not found") -> 17.5 | BI8: BMW | BJ8: Dodge
B9: Units Sold | C9: =IFERROR(INDEX('Cleaned Data'!D:D,MATCH($C$5,'Cleaned Data'!B:B,0)),"Model not found") -> 5.596 | BI9: BMW | BJ9: Ford
B10: Revenue, $M | C10: =IFERROR(INDEX('Cleaned Data'!S:S,MATCH($C$5,'Cleaned Data'!B:B,0)),"Model not found") -> 97.93 | BI10: BMW | BJ10: Honda
B11: Vehicle Segment | C11: =IFERROR(INDEX('Cleaned Data'!C:C,MATCH($C$5,'Cleaned Data'!B:B,0)),"Model not found") -> Passenger Car | BI11: Buick | BJ11: Hyundai
B12: Price Tier | C12: =IFERROR(INDEX('Cleaned Data'!T:T,MATCH($C$5,'Cleaned Data'!B:B,0)),"Model not found") -> Mid-range | BI12: Buick | BJ12: Infiniti
B13: Sales Rank (1 = highest) | C13: =IFERROR(INDEX('Cleaned Data'!V:V,MATCH($C$5,'Cleaned Data'!B:B,0)),"Model not found") -> 141 | BI13: Buick | BJ13: Jaguar
B14: Launch Date | C14: =IFERROR(INDEX('Cleaned Data'!O:O,MATCH($C$5,'Cleaned Data'!B:B,0)),"Model not found") -> 40634 | BI14: Buick | BJ14: Jeep
BI15: Cadillac | BJ15: Lexus
BI16: Cadillac | BJ16: Lincoln
B17: Brand Lookup (VLOOKUP against Analysis!Brand Summary) | BI17: Cadillac | BJ17: Mitsubishi
B18: Search Brand: | C18: Chevrolet | BI18: Cadillac | BJ18: Mercury
B19: Total Units Sold | C19: =IFERROR(VLOOKUP($C$18,Analysis!$B$5:$H$36,2,FALSE()),"Brand not found") -> 554.365 | BI19: Cadillac | BJ19: Mercedes-Benz
B20: Total Revenue, $ | C20: =IFERROR(VLOOKUP($C$18,Analysis!$B$5:$H$36,3,FALSE()),"Brand not found") -> 9610.6533 | BI20: Chevrolet | BJ20: Nissan
B21: Average Price, $ | C21: =IFERROR(VLOOKUP($C$18,Analysis!$B$5:$H$36,4,FALSE()),"Brand not found") -> 20.022778 | BI21: Chevrolet | BJ21: Oldsmobile
B22: Number of Models | C22: =IFERROR(VLOOKUP($C$18,Analysis!$B$5:$H$36,5,FALSE()),"Brand not found") -> 9 | BI22: Chevrolet | BJ22: Plymouth
B23: Revenue Rank | C23: =IFERROR(VLOOKUP($C$18,Analysis!$B$5:$H$36,7,FALSE()),"Brand not found") -> 5 | BI23: Chevrolet | BJ23: Pontiac
BI24: Chevrolet | BJ24: Porsche
BI25: Chevrolet | BJ25: Saab
BI26: Chevrolet | BJ26: Saturn
BI27: Chevrolet | BJ27: Subaru
BI28: Chevrolet | BJ28: Toyota
BI29: Chrysler | BJ29: Volkswagen
BI30: Chrysler | BJ30: Volvo
BI31: Chrysler
BI32: Chrysler
BI33: Chrysler
BI34: Chrysler
BI35: Chrysler
BI36: Dodge
BI37: Dodge
BI38: Dodge
BI39: Dodge
BI40: Dodge
...

Sheet Business Answers
B2: Business Questions — Answered Live with Formulas
B4: Which car brand generates the highest revenue?
B5: =INDEX(Analysis!$B$6:$B$35,MATCH(MAX(Analysis!$D$6:$D$35),Analysis!$D$6:$D$35,0))&" ($"&TEXT(MAX(Analysis!$D$6:$D$35),"#,##0.0")&"M)" -> Ford ($45,776.1M)
B7: Which model sells the most?
B8: =Analysis!C58&" ("&TEXT(Analysis!E58,"#,##0.0")&"k units)" -> F-Series (540.6k units)
B10: Which launch year has the highest total sales? (proxy for "highest month" — no monthly data exists)
B11: =INDEX(Analysis!$B$51:$B$54,MATCH(MAX(Analysis!$C$51:$C$54),Analysis!$C$51:$C$54,0)) -> 2012
B13: What is the average selling price across all models?
B14: ="$"&TEXT(AVERAGE('Cleaned Data'!$E$2:$E$158),"#,##0.0")&"k" -> $27.4k
B16: Which brands have the highest average price?
B17: =INDEX(Analysis!$B$6:$B$35,MATCH(MAX(Analysis!$E$6:$E$35),Analysis!$E$6:$E$35,0))&" (avg $"&TEXT(MAX(Analysis!$E$6:$E$35),"#,##0.0")&"k)" -> Porsche (avg $62.5k)
B19: Are expensive cars selling less than cheaper cars?
B20: =IF(CORREL('Cleaned Data'!$E$2:$E$158,'Cleaned Data'!$D$2:$D$158)<0,"Yes — price and units sold are negatively correlated (correlation: "&TEXT(CORREL('Cleaned Data'!$E$2:$E$158,'Cleaned Data'!$D$2:$D$158),"0.00")&"). See the Price vs Units Sold scatter chart.","No clear negative relationship (correlation: "&TEXT(CORREL('Cleaned Data'!$E$2:$E$158,'Cleaned Data'!$D$2:$D$158),"0.00")&").") -> Yes — price and units sold are negatively correlated (correlation: -0.30). See the Price vs Units Sold scatter chart.
